<robot
  name="scara_setup">
  
  <gazebo>
		<plugin name="gazebo_ros_control" filename="libgazebo_ros_control.so">
			<robotNamespace>/scara_setup</robotNamespace>
			<robotSimType>gazebo_ros_control/DefaultRobotHWSim</robotSimType>
		</plugin>
	</gazebo>
  
  <link name="world"/>
  
  <link name="mount_point"/>
  <link name="effector_tip" />
  
  <link
    name="frame">
    <inertial>
      <origin
        xyz="-1.3962E-17 -0.0032126 0.261"
        rpy="0 0 0" />
      <mass
        value="1.493" />
      <inertia
        ixx="0.035804"
        ixy="5.4774E-19"
        ixz="-2.3172E-18"
        iyy="0.036324"
        iyz="-3.2402E-18"
        izz="0.0007275" />
    </inertial>
    <visual>
      <origin
        xyz="0 0 0"
        rpy="0 0 0" />
      <geometry>
        <mesh
          filename="package://scara_setup_description/meshes/frame.STL" />
      </geometry>
      <material
        name="">
        <color
          rgba="0.10196 0.10196 0.10196 1" />
      </material>
    </visual>
    <collision>
      <origin
        xyz="0 0 0"
        rpy="0 0 0" />
      <geometry>
        <mesh
          filename="package://scara_setup_description/meshes/frame.STL" />
      </geometry>
    </collision>
  </link>
  <link
    name="cart">
    <inertial>
      <origin
        xyz="2.8028E-18 0.049288 0.0065656"
        rpy="0 0 0" />
      <mass
        value="1.2925" />
      <inertia
        ixx="0.0030664"
        ixy="-1.3057E-19"
        ixz="5.1704E-19"
        iyy="0.001007"
        iyz="7.8657E-05"
        izz="0.0026482" />
    </inertial>
    <visual>
      <origin
        xyz="0 0 0"
        rpy="0 0 0" />
      <geometry>
        <mesh
          filename="package://scara_setup_description/meshes/cart.STL" />
      </geometry>
      <material
        name="">
        <color
          rgba="0.75294 0.75294 0.75294 1" />
      </material>
    </visual>
    <collision>
      <origin
        xyz="0 0 0"
        rpy="0 0 0" />
      <geometry>
        <mesh
          filename="package://scara_setup_description/meshes/cart.STL" />
      </geometry>
    </collision>
  </link>
  <joint
    name="linear"
    type="prismatic">
    <origin
      xyz="0 0.0159 0.049"
      rpy="1.3878E-15 -1.3878E-15 -7.9703E-17" />
    <parent
      link="frame" />
    <child
      link="cart" />
    <axis
      xyz="0 0 1" />
    <limit
      lower="0"
      upper="0.424"
      effort="501"
      velocity="0.0063" />
  </joint>
  <link
    name="arm">
    <inertial>
      <origin
        xyz="-4.8333E-17 0.175 -0.020313"
        rpy="0 0 0" />
      <mass
        value="0.81408" />
      <inertia
        ixx="0.018293"
        ixy="-2.8864E-18"
        ixz="-2.2791E-20"
        iyy="0.00019071"
        iyz="1.1001E-19"
        izz="0.018314" />
    </inertial>
    <visual>
      <origin
        xyz="0 0 0"
        rpy="0 0 0" />
      <geometry>
        <mesh
          filename="package://scara_setup_description/meshes/arm.STL" />
      </geometry>
      <material
        name="">
        <color
          rgba="0.75294 0.75294 0.75294 1" />
      </material>
    </visual>
    <collision>
      <origin
        xyz="0 0 0"
        rpy="0 0 0" />
      <geometry>
        <mesh
          filename="package://scara_setup_description/meshes/arm.STL" />
      </geometry>
    </collision>
  </link>
  <joint
    name="shoulder"
    type="revolute">
    <origin
      xyz="0 0.11311 -0.0285"
      rpy="-1.3878E-15 1.3878E-15 7.9703E-17" />
    <parent
      link="cart" />
    <child
      link="arm" />
    <axis
      xyz="0 0 1" />
    <limit
      lower="-1.57"
      upper="1.57"
      effort="6"
      velocity="3.295" />
  </joint>
  <link
    name="forearm">
    <inertial>
      <origin
        xyz="1.6424E-16 0.15861 0.035158"
        rpy="0 0 0" />
      <mass
        value="1.2555" />
      <inertia
        ixx="0.036347"
        ixy="9.1469E-18"
        ixz="8.7884E-19"
        iyy="0.00068775"
        iyz="-0.0009169"
        izz="0.036003" />
    </inertial>
    <visual>
      <origin
        xyz="0 0 0"
        rpy="0 0 0" />
      <geometry>
        <mesh
          filename="package://scara_setup_description/meshes/forearm.STL" />
      </geometry>
      <material
        name="">
        <color
          rgba="0.75294 0.75294 0.75294 1" />
      </material>
    </visual>
    <collision>
      <origin
        xyz="0 0 0"
        rpy="0 0 0" />
      <geometry>
        <mesh
          filename="package://scara_setup_description/meshes/forearm.STL" />
      </geometry>
    </collision>
  </link>
  <joint
    name="elbow"
    type="revolute">
    <origin
      xyz="0 0.35 0"
      rpy="6.9389E-16 -2.0817E-15 -1.4444E-30" />
    <parent
      link="arm" />
    <child
      link="forearm" />
    <axis
      xyz="0 0 1" />
    <limit
      lower="-1.57"
      upper="1.57"
      effort="6"
      velocity="3.295" />
  </joint>
  <link
    name="hand">
    <inertial>
      <origin
        xyz="5.4351E-17 0.036943 0.039218"
        rpy="0 0 0" />
      <mass
        value="0.79174" />
      <inertia
        ixx="0.0012079"
        ixy="2.1009E-19"
        ixz="7.5749E-19"
        iyy="0.0005451"
        iyz="0.00014942"
        izz="0.00089052" />
    </inertial>
    <visual>
      <origin
        xyz="0 0 0"
        rpy="0 0 0" />
      <geometry>
        <mesh
          filename="package://scara_setup_description/meshes/hand.STL" />
      </geometry>
      <material
        name="">
        <color
          rgba="0.75294 0.75294 0.75294 1" />
      </material>
    </visual>
    <collision>
      <origin
        xyz="0 0 0"
        rpy="0 0 0" />
      <geometry>
        <mesh
          filename="package://scara_setup_description/meshes/hand.STL" />
      </geometry>
    </collision>
  </link>
  <joint
    name="wrist"
    type="revolute">
    <origin
      xyz="0 0.42501 0.0485"
      rpy="-6.9389E-16 2.0817E-15 0" />
    <parent
      link="forearm" />
    <child
      link="hand" />
    <axis
      xyz="0 0 1" />
    <limit
      lower="-1.57"
      upper="1.57"
      effort="6"
      velocity="3.295" />
  </joint>
  <link
    name="finger">
    <inertial>
      <origin
        xyz="-1.0164E-17 0.013252 -9.7145E-17"
        rpy="0 0 0" />
      <mass
        value="0.18562" />
      <inertia
        ixx="6.2332E-05"
        ixy="-2.6264E-20"
        ixz="-2.6844E-20"
        iyy="4.051E-05"
        iyz="-3.3964E-21"
        izz="7.0561E-05" />
    </inertial>
    <visual>
      <origin
        xyz="0 0 0"
        rpy="0 0 0" />
      <geometry>
        <mesh
          filename="package://scara_setup_description/meshes/finger.STL" />
      </geometry>
      <material
        name="">
        <color
          rgba="0.75294 0.75294 0.75294 1" />
      </material>
    </visual>
    <collision>
      <origin
        xyz="0 0 0"
        rpy="0 0 0" />
      <geometry>
        <mesh
          filename="package://scara_setup_description/meshes/finger.STL" />
      </geometry>
    </collision>
  </link>
  <joint
    name="fingerjoint"
    type="revolute">
    <origin
      xyz="0 0.14311 0.0285"
      rpy="0 -1.3878E-15 0" />
    <parent
      link="hand" />
    <child
      link="finger" />
    <axis
      xyz="-1 0 0" />
    <limit
      lower="-2.57"
      upper="2.57"
      effort="1.5"
      velocity="370.7" />
  </joint>
  
  <joint name="dummy" type="fixed">
  	<origin xyz="0 0 0" rpy="0 0 0"/>
  	<parent link="mount_point"/>
  	<child link="frame"/>
  </joint>
  
  <joint name="tip_joint" type="fixed">
  	<origin xyz="0 0.0665 0" rpy="0 0 0"/>
  	<parent link="finger"/>
  	<child link="effector_tip"/>
  </joint>
  
	<transmission name="transmissionlinear">
		<type>transmission_interface/SimpleTransmission</type>
		<joint name="linear">
			<hardwareInterface>EffortJointInterface</hardwareInterface>
		</joint>
		<actuator name="motorlinear">
			<hardwareInterface>EffortJointInterface</hardwareInterface>
			<mechanicalReduction>167</mechanicalReduction>
		</actuator>
	</transmission>
	
	<transmission name="transmissionshoulder">
		<type>transmission_interface/SimpleTransmission</type>
		<joint name="shoulder">
			<hardwareInterface>EffortJointInterface</hardwareInterface>
		</joint>
		<actuator name="motorshoulder">
			<hardwareInterface>EffortJointInterface</hardwareInterface>
			<mechanicalReduction>2</mechanicalReduction>
		</actuator>
	</transmission>
	
	<transmission name="transmissionelbow">
		<type>transmission_interface/SimpleTransmission</type>
		<joint name="elbow">
			<hardwareInterface>EffortJointInterface</hardwareInterface>
		</joint>
		<actuator name="motorelbow">
			<hardwareInterface>EffortJointInterface</hardwareInterface>
			<mechanicalReduction>2</mechanicalReduction>
		</actuator>
	</transmission>
	
	<transmission name="transmissionwrist">
		<type>transmission_interface/SimpleTransmission</type>
		<joint name="wrist">
			<hardwareInterface>EffortJointInterface</hardwareInterface>
		</joint>
		<actuator name="motorwrist">
			<hardwareInterface>EffortJointInterface</hardwareInterface>
			<mechanicalReduction>2</mechanicalReduction>
		</actuator>
	</transmission>
	
	<transmission name="transmissionfinger">
		<type>transmission_interface/SimpleTransmission</type>
		<joint name="fingerjoint">
			<hardwareInterface>EffortJointInterface</hardwareInterface>
		</joint>
		<actuator name="motorfinger">
			<hardwareInterface>EffortJointInterface</hardwareInterface>
			<mechanicalReduction>1</mechanicalReduction>
		</actuator>
	</transmission>
	
	<joint name="fixed" type="fixed">
		<origin xyz="0 0 0.3" rpy="0 0 0"/>
		<parent link="world"/>
		<child link="mount_point"/>
	</joint>
</robot>
