<robot
  name="scara_setup">
  
  <gazebo>
		<plugin name="gazebo_ros_control" filename="libgazebo_ros_control.so">
			<robotNamespace>/scara_setup</robotNamespace>
			<robotSimType>gazebo_ros_control/DefaultRobotHWSim</robotSimType>
		</plugin>
	</gazebo>
  
  <link name="world"/>
  
  <link name="mount_point"/>
  <link name="effector_tip" />
  
  <link
    name="frame">
    <inertial>
      <origin
        xyz="1.3981E-17 0.261 -0.0032126"
        rpy="0 0 0" />
      <mass
        value="1.493" />
      <inertia
        ixx="0.035804"
        ixy="2.2733E-18"
        ixz="-5.475E-19"
        iyy="0.0007275"
        iyz="-3.2317E-18"
        izz="0.036324" />
    </inertial>
    <visual>
      <origin
        xyz="0 0 0"
        rpy="0 0 0" />
      <geometry>
        <mesh
          filename="package://scara_setup_description/meshes/base_link.STL" />
      </geometry>
      <material
        name="">
        <color
          rgba="0.10196 0.10196 0.10196 1" />
      </material>
    </visual>
    <collision>
      <origin
        xyz="0 0 0"
        rpy="0 0 0" />
      <geometry>
        <mesh
          filename="package://scara_setup_description/meshes/base_link.STL" />
      </geometry>
    </collision>
  </link>
  <link
    name="cart">
    <inertial>
      <origin
        xyz="3.2748E-17 0.046688 -0.0065656"
        rpy="0 0 0" />
      <mass
        value="1.2925" />
      <inertia
        ixx="0.0030664"
        ixy="7.5083E-20"
        ixz="-6.4252E-20"
        iyy="0.001007"
        iyz="-7.8657E-05"
        izz="0.0026482" />
    </inertial>
    <visual>
      <origin
        xyz="0 0 0"
        rpy="0 0 0" />
      <geometry>
        <mesh
          filename="package://scara_setup_description/meshes/cart.STL" />
      </geometry>
      <material
        name="">
        <color
          rgba="0.75294 0.75294 0.75294 1" />
      </material>
    </visual>
    <collision>
      <origin
        xyz="0 0 0"
        rpy="0 0 0" />
      <geometry>
        <mesh
          filename="package://scara_setup_description/meshes/cart.STL" />
      </geometry>
    </collision>
  </link>
  <joint
    name="linear"
    type="prismatic">
    <origin
      xyz="0 -0.0185 0.049001"
      rpy="3.1416 0 0" />
    <parent
      link="frame" />
    <child
      link="cart" />
    <axis
      xyz="0 0 -1" />
    <limit
      lower="0"
      upper="0.424"
      effort="500"
      velocity="0.3" />
  </joint>
  <link
    name="arm">
    <inertial>
      <origin
        xyz="-0.175 -0.020313 9.0057E-17"
        rpy="0 0 0" />
      <mass
        value="0.81408" />
      <inertia
        ixx="0.00019071"
        ixy="-1.3129E-19"
        ixz="-4.0555E-18"
        iyy="0.018314"
        iyz="2.0111E-20"
        izz="0.018293" />
    </inertial>
    <visual>
      <origin
        xyz="0 0 0"
        rpy="0 0 0" />
      <geometry>
        <mesh
          filename="package://scara_setup_description/meshes/arm.STL" />
      </geometry>
      <material
        name="">
        <color
          rgba="0.75294 0.75294 0.75294 1" />
      </material>
    </visual>
    <collision>
      <origin
        xyz="0 0 0"
        rpy="0 0 0" />
      <geometry>
        <mesh
          filename="package://scara_setup_description/meshes/arm.STL" />
      </geometry>
    </collision>
  </link>
  <joint
    name="shoulder"
    type="revolute">
    <origin
      xyz="0 0.11051 0.0285"
      rpy="-1.5708 0 -1.5708" />
    <parent
      link="cart" />
    <child
      link="arm" />
    <axis
      xyz="0 1 0" />
    <limit
      lower="-1.57"
      upper="1.57"
      effort="6"
      velocity="198" />
  </joint>
  <link
    name="forearm">
    <inertial>
      <origin
        xyz="0.15861 0.033658 4.431E-17"
        rpy="0 0 0" />
      <mass
        value="1.2555" />
      <inertia
        ixx="0.00068775"
        ixy="-0.0009169"
        ixz="1.3219E-17"
        iyy="0.036003"
        iyz="9.4114E-20"
        izz="0.036347" />
    </inertial>
    <visual>
      <origin
        xyz="0 0 0"
        rpy="0 0 0" />
      <geometry>
        <mesh
          filename="package://scara_setup_description/meshes/forearm.STL" />
      </geometry>
      <material
        name="">
        <color
          rgba="0.75294 0.75294 0.75294 1" />
      </material>
    </visual>
    <collision>
      <origin
        xyz="0 0 0"
        rpy="0 0 0" />
      <geometry>
        <mesh
          filename="package://scara_setup_description/meshes/forearm.STL" />
      </geometry>
    </collision>
  </link>
  <joint
    name="elbow"
    type="revolute">
    <origin
      xyz="-0.35 0.0015 0"
      rpy="3.1416 -1.2246E-16 3.1416" />
    <parent
      link="arm" />
    <child
      link="forearm" />
    <axis
      xyz="0 1 0" />
    <limit
      lower="-1.57"
      upper="1.57"
      effort="6"
      velocity="198" />
  </joint>
  <link
    name="hand">
    <inertial>
      <origin
        xyz="-0.036943 0.037718 -1.8058E-16"
        rpy="0 0 0" />
      <mass
        value="0.79174" />
      <inertia
        ixx="0.0005451"
        ixy="-0.00014942"
        ixz="1.8117E-19"
        iyy="0.00089052"
        iyz="-7.4805E-19"
        izz="0.0012079" />
    </inertial>
    <visual>
      <origin
        xyz="0 0 0"
        rpy="0 0 0" />
      <geometry>
        <mesh
          filename="package://scara_setup_description/meshes/hand.STL" />
      </geometry>
      <material
        name="">
        <color
          rgba="0.75294 0.75294 0.75294 1" />
      </material>
    </visual>
    <collision>
      <origin
        xyz="0 0 0"
        rpy="0 0 0" />
      <geometry>
        <mesh
          filename="package://scara_setup_description/meshes/hand.STL" />
      </geometry>
    </collision>
  </link>
  <joint
    name="wrist"
    type="revolute">
    <origin
      xyz="0.42501 0.0485 0"
      rpy="3.1416 1.2246E-16 3.1416" />
    <parent
      link="forearm" />
    <child
      link="hand" />
    <axis
      xyz="0 1 0" />
    <limit
      lower="-1.57"
      upper="1.57"
      effort="6"
      velocity="198" />
  </joint>
  <link
    name="finger">
    <inertial>
      <origin
        xyz="0.0017522 -0.02 2.7756E-17"
        rpy="0 0 0" />
      <mass
        value="0.18562" />
      <inertia
        ixx="4.051E-05"
        ixy="-2.252E-20"
        ixz="3.2672E-20"
        iyy="6.2332E-05"
        iyz="6.5888E-21"
        izz="7.0561E-05" />
    </inertial>
    <visual>
      <origin
        xyz="0 0 0"
        rpy="0 0 0" />
      <geometry>
        <mesh
          filename="package://scara_setup_description/meshes/finger.STL" />
      </geometry>
      <material
        name="">
        <color
          rgba="0.75294 0.75294 0.75294 1" />
      </material>
    </visual>
    <collision>
      <origin
        xyz="0 0 0"
        rpy="0 0 0" />
      <geometry>
        <mesh
          filename="package://scara_setup_description/meshes/finger.STL" />
      </geometry>
    </collision>
  </link>
  <joint
    name="fingerjoint"
    type="revolute">
    <origin
      xyz="-0.15461 0.027 -0.02"
      rpy="-1.5708 -6.123E-17 3.1416" />
    <parent
      link="hand" />
    <child
      link="finger" />
    <axis
      xyz="0 -1 0" />
    <limit
      lower="-1.57"
      upper="1.57"
      effort="1.5"
      velocity="370" />
  </joint>
  
  <joint name="dummy" type="fixed">
  	<origin xyz="0 0 0" rpy="0 0 0"/>
  	<parent link="mount_point"/>
  	<child link="frame"/>
  </joint>
  
  <joint name="tip_joint" type="fixed">
  	<origin xyz="0.0665 0 0" rpy="1.57 0 0"/>
  	<parent link="finger"/>
  	<child link="effector_tip"/>
  </joint>
  
	<transmission name="transmissionlinear">
		<type>transmission_interface/SimpleTransmission</type>
		<joint name="linear">
			<hardwareInterface>EffortJointInterface</hardwareInterface>
		</joint>
		<actuator name="motorlinear">
			<hardwareInterface>EffortJointInterface</hardwareInterface>
			<mechanicalReduction>167</mechanicalReduction>
		</actuator>
	</transmission>
	
	<transmission name="transmissionshoulder">
		<type>transmission_interface/SimpleTransmission</type>
		<joint name="shoulder">
			<hardwareInterface>EffortJointInterface</hardwareInterface>
		</joint>
		<actuator name="motorshoulder">
			<hardwareInterface>EffortJointInterface</hardwareInterface>
			<mechanicalReduction>2</mechanicalReduction>
		</actuator>
	</transmission>
	
	<transmission name="transmissionelbow">
		<type>transmission_interface/SimpleTransmission</type>
		<joint name="elbow">
			<hardwareInterface>EffortJointInterface</hardwareInterface>
		</joint>
		<actuator name="motorelbow">
			<hardwareInterface>EffortJointInterface</hardwareInterface>
			<mechanicalReduction>2</mechanicalReduction>
		</actuator>
	</transmission>
	
	<transmission name="transmissionwrist">
		<type>transmission_interface/SimpleTransmission</type>
		<joint name="wrist">
			<hardwareInterface>EffortJointInterface</hardwareInterface>
		</joint>
		<actuator name="motorwrist">
			<hardwareInterface>EffortJointInterface</hardwareInterface>
			<mechanicalReduction>2</mechanicalReduction>
		</actuator>
	</transmission>
	
	<transmission name="transmissionfinger">
		<type>transmission_interface/SimpleTransmission</type>
		<joint name="fingerjoint">
			<hardwareInterface>EffortJointInterface</hardwareInterface>
		</joint>
		<actuator name="motorfinger">
			<hardwareInterface>EffortJointInterface</hardwareInterface>
			<mechanicalReduction>1</mechanicalReduction>
		</actuator>
	</transmission>
	
	<joint name="fixed" type="fixed">
		<origin xyz="0 0 0.3" rpy="0 0 0"/>
		<parent link="world"/>
		<child link="mount_point"/>
	</joint>
</robot>
