<?xml version="1.0" ?>
<!-- =================================================================================== -->
<!-- |    This document was autogenerated by xacro from scara.urdf.xacro               | -->
<!-- |    EDITING THIS FILE BY HAND IS NOT RECOMMENDED                                 | -->
<!-- =================================================================================== -->
<robot name="scara_arm" xmlns:xacro="http://www.ros.org/wiki/xacro">
  <link name="base_link">
    <visual>
      <geometry>
        <cylinder length="0.115" radius="0.095"/>
      </geometry>
      <origin rpy="0 1.57079632679 0" xyz="0.0575 0 0"/>
      <material name="aluminium">
        <color rgba="0.9 0.9 0.9 1"/>
      </material>
    </visual>
    <collision>
      <geometry>
        <cylinder length="0.115" radius="0.1"/>
      </geometry>
      <origin rpy="0 1.57079632679 0" xyz="0.115 0 0"/>
    </collision>
  </link>
  <link name="arm">
    <visual>
      <geometry>
        <cylinder length="0.425" radius="0.015"/>
      </geometry>
      <origin rpy="0 1.57079632679 0" xyz="0.2125 0 0"/>
      <material name="carbon">
        <color rgba="0.1 0.1 0.1 1"/>
      </material>
    </visual>
    <collision>
      <geometry>
        <cylinder length="0.425" radius="0.02"/>
      </geometry>
      <origin rpy="0 1.57079632679 0" xyz="0.2125 0 0"/>
    </collision>
  </link>
  <link name="fore_arm">
    <visual>
      <geometry>
        <cylinder length="0.35" radius="0.015"/>
      </geometry>
      <origin rpy="0 1.57079632679 0" xyz="0.175 0 0"/>
      <material name="carbon"/>
    </visual>
    <collision>
      <geometry>
        <cylinder length="0.35" radius="0.02"/>
      </geometry>
      <origin rpy="0 1.57079632679 0" xyz="0.175 0 0"/>
    </collision>
  </link>
  <link name="effector">
    <visual>
      <geometry>
        <cylinder length="0.115" radius="0.014"/>
      </geometry>
      <origin rpy="0 1.57079632679 0" xyz="0.0575 0 0"/>
      <material name="aluminium"/>
    </visual>
    <collision>
      <geometry>
        <cylinder length="0.115" radius="0.019"/>
      </geometry>
      <origin rpy="0 1.57079632679 0" xyz="0.0575 0 0"/>
    </collision>
  </link>
  <link name="tool0"/>
  <joint name="shoulder" type="revolute">
    <parent link="base_link"/>
    <child link="arm"/>
    <origin rpy="0 0 0" xyz="0.115 0 0.05"/>
    <axis xyz="0 0 1"/>
    <limit effort="1000.0" lower="-2.35619449019" upper="2.35619449019" velocity="0.5"/>
  </joint>
  <joint name="elbow" type="revolute">
    <parent link="arm"/>
    <child link="fore_arm"/>
    <origin rpy="0 0 0" xyz="0.425 0 0.05"/>
    <axis xyz="0 0 1"/>
    <limit effort="1000.0" lower="-2.98" upper="2.98" velocity="0.5"/>
  </joint>
  <joint name="wrist" type="revolute">
    <parent link="fore_arm"/>
    <child link="effector"/>
    <origin rpy="0 0 0" xyz="0.35 0 -0.05"/>
    <axis xyz="0 0 1"/>
    <limit effort="1000.0" lower="-2.98" upper="2.98" velocity="0.5"/>
  </joint>
  <joint name="joint_tool" type="fixed">
    <parent link="effector"/>
    <child link="tool0"/>
    <origin rpy="0 0 0" xyz="0 0 0"/>
  </joint>
</robot>

